[2022-07-23 08:59:46,627] {taskinstance.py:1179} INFO - Dependencies all met for <TaskInstance: local_to_snowflake.add_upload_date manual__2022-07-23T08:59:38.113510+00:00 [queued]>
[2022-07-23 08:59:46,659] {taskinstance.py:1179} INFO - Dependencies all met for <TaskInstance: local_to_snowflake.add_upload_date manual__2022-07-23T08:59:38.113510+00:00 [queued]>
[2022-07-23 08:59:46,659] {taskinstance.py:1376} INFO - 
--------------------------------------------------------------------------------
[2022-07-23 08:59:46,659] {taskinstance.py:1377} INFO - Starting attempt 1 of 1
[2022-07-23 08:59:46,659] {taskinstance.py:1378} INFO - 
--------------------------------------------------------------------------------
[2022-07-23 08:59:46,747] {taskinstance.py:1397} INFO - Executing <Task(_PythonDecoratedOperator): add_upload_date> on 2022-07-23 08:59:38.113510+00:00
[2022-07-23 08:59:46,790] {standard_task_runner.py:52} INFO - Started process 378 to run task
[2022-07-23 08:59:46,827] {standard_task_runner.py:79} INFO - Running: ['***', 'tasks', 'run', 'local_to_snowflake', 'add_upload_date', 'manual__2022-07-23T08:59:38.113510+00:00', '--job-id', '41', '--raw', '--subdir', 'DAGS_FOLDER/localtosnowflake.py', '--cfg-path', '/tmp/tmp_e9e86c1', '--error-file', '/tmp/tmp37biewl5']
[2022-07-23 08:59:46,831] {standard_task_runner.py:80} INFO - Job 41: Subtask add_upload_date
[2022-07-23 08:59:47,224] {task_command.py:371} INFO - Running <TaskInstance: local_to_snowflake.add_upload_date manual__2022-07-23T08:59:38.113510+00:00 [running]> on host d30608300872
[2022-07-23 08:59:47,746] {taskinstance.py:1591} INFO - Exporting the following env vars:
AIRFLOW_CTX_DAG_OWNER=***
AIRFLOW_CTX_DAG_ID=local_to_snowflake
AIRFLOW_CTX_TASK_ID=add_upload_date
AIRFLOW_CTX_EXECUTION_DATE=2022-07-23T08:59:38.113510+00:00
AIRFLOW_CTX_TRY_NUMBER=1
AIRFLOW_CTX_DAG_RUN_ID=manual__2022-07-23T08:59:38.113510+00:00
[2022-07-23 08:59:47,749] {taskinstance.py:1909} ERROR - Task failed with exception
Traceback (most recent call last):
  File "/home/airflow/.local/lib/python3.7/site-packages/airflow/decorators/base.py", line 179, in execute
    return_value = super().execute(context)
  File "/home/airflow/.local/lib/python3.7/site-packages/airflow/operators/python.py", line 171, in execute
    return_value = self.execute_callable()
  File "/home/airflow/.local/lib/python3.7/site-packages/airflow/operators/python.py", line 189, in execute_callable
    return self.python_callable(*self.op_args, **self.op_kwargs)
  File "/opt/airflow/dags/localtosnowflake.py", line 37, in add_upload_date
    trip_dict = pd.read_csv(
NameError: name 'pd' is not defined
[2022-07-23 08:59:47,803] {taskinstance.py:1420} INFO - Marking task as FAILED. dag_id=local_to_snowflake, task_id=add_upload_date, execution_date=20220723T085938, start_date=20220723T085946, end_date=20220723T085947
[2022-07-23 08:59:47,872] {standard_task_runner.py:97} ERROR - Failed to execute job 41 for task add_upload_date (name 'pd' is not defined; 378)
[2022-07-23 08:59:47,905] {local_task_job.py:156} INFO - Task exited with return code 1
[2022-07-23 08:59:48,082] {local_task_job.py:273} INFO - 0 downstream tasks scheduled from follow-on schedule check
