[2022-07-23 09:06:58,906] {taskinstance.py:1179} INFO - Dependencies all met for <TaskInstance: local_to_snowflake.create_snowflake_table manual__2022-07-23T09:06:34.194905+00:00 [queued]>
[2022-07-23 09:06:58,929] {taskinstance.py:1179} INFO - Dependencies all met for <TaskInstance: local_to_snowflake.create_snowflake_table manual__2022-07-23T09:06:34.194905+00:00 [queued]>
[2022-07-23 09:06:58,930] {taskinstance.py:1376} INFO - 
--------------------------------------------------------------------------------
[2022-07-23 09:06:58,930] {taskinstance.py:1377} INFO - Starting attempt 1 of 1
[2022-07-23 09:06:58,930] {taskinstance.py:1378} INFO - 
--------------------------------------------------------------------------------
[2022-07-23 09:06:58,979] {taskinstance.py:1397} INFO - Executing <Task(SnowflakeOperator): create_snowflake_table> on 2022-07-23 09:06:34.194905+00:00
[2022-07-23 09:06:58,997] {standard_task_runner.py:52} INFO - Started process 176 to run task
[2022-07-23 09:06:59,009] {standard_task_runner.py:79} INFO - Running: ['***', 'tasks', 'run', 'local_to_snowflake', 'create_snowflake_table', 'manual__2022-07-23T09:06:34.194905+00:00', '--job-id', '49', '--raw', '--subdir', 'DAGS_FOLDER/localtosnowflake.py', '--cfg-path', '/tmp/tmpznazvytn', '--error-file', '/tmp/tmpkhmirlp3']
[2022-07-23 09:06:59,023] {standard_task_runner.py:80} INFO - Job 49: Subtask create_snowflake_table
[2022-07-23 09:06:59,195] {task_command.py:371} INFO - Running <TaskInstance: local_to_snowflake.create_snowflake_table manual__2022-07-23T09:06:34.194905+00:00 [running]> on host cbd64c50b1d6
[2022-07-23 09:06:59,462] {taskinstance.py:1909} ERROR - Task failed with exception
Traceback (most recent call last):
  File "/home/airflow/.local/lib/python3.7/site-packages/airflow/models/taskinstance.py", line 1471, in _run_raw_task
    self._execute_task_with_callbacks(context, test_mode)
  File "/home/airflow/.local/lib/python3.7/site-packages/airflow/models/taskinstance.py", line 1575, in _execute_task_with_callbacks
    task_orig = self.render_templates(context=context)
  File "/home/airflow/.local/lib/python3.7/site-packages/airflow/models/taskinstance.py", line 2232, in render_templates
    rendered_task = self.task.render_template_fields(context)
  File "/home/airflow/.local/lib/python3.7/site-packages/airflow/models/baseoperator.py", line 1188, in render_template_fields
    self._do_render_template_fields(self, self.template_fields, context, jinja_env, set())
  File "/home/airflow/.local/lib/python3.7/site-packages/airflow/utils/session.py", line 71, in wrapper
    return func(*args, session=session, **kwargs)
  File "/home/airflow/.local/lib/python3.7/site-packages/airflow/models/abstractoperator.py", line 347, in _do_render_template_fields
    seen_oids,
  File "/home/airflow/.local/lib/python3.7/site-packages/airflow/models/abstractoperator.py", line 390, in render_template
    return render_template_to_string(template, context)
  File "/home/airflow/.local/lib/python3.7/site-packages/airflow/utils/helpers.py", line 296, in render_template_to_string
    return render_template(template, context, native=False)
  File "/home/airflow/.local/lib/python3.7/site-packages/airflow/utils/helpers.py", line 291, in render_template
    return "".join(nodes)
  File "<template>", line 12, in root
  File "/opt/airflow/sqlfile/create_snowflake_yellow_tripdata_table.sql", line 14, in root
    mta_tax float,
  File "/home/airflow/.local/lib/python3.7/site-packages/jinja2/sandbox.py", line 326, in getattr
    value = getattr(obj, attribute)
  File "/home/airflow/.local/lib/python3.7/site-packages/airflow/utils/context.py", line 123, in __getattr__
    self.var = Connection.get_connection_from_secrets(key)
  File "/home/airflow/.local/lib/python3.7/site-packages/airflow/models/connection.py", line 430, in get_connection_from_secrets
    raise AirflowNotFoundException(f"The conn_id `{conn_id}` isn't defined")
airflow.exceptions.AirflowNotFoundException: The conn_id `snowflake_default` isn't defined
[2022-07-23 09:06:59,487] {taskinstance.py:1420} INFO - Marking task as FAILED. dag_id=local_to_snowflake, task_id=create_snowflake_table, execution_date=20220723T090634, start_date=20220723T090658, end_date=20220723T090659
[2022-07-23 09:06:59,543] {standard_task_runner.py:97} ERROR - Failed to execute job 49 for task create_snowflake_table (The conn_id `snowflake_default` isn't defined; 176)
[2022-07-23 09:06:59,559] {local_task_job.py:156} INFO - Task exited with return code 1
[2022-07-23 09:06:59,660] {local_task_job.py:273} INFO - 0 downstream tasks scheduled from follow-on schedule check
